Workbook

Sheet Comece Aqui
H2: 01. Siga a ordem das abas.
H4: As abas estão na ordem correta para você entrar com os
H5: dados necessários em cada uma delas. Não pule etapas.
B7: Como Usar | H7: 02. Altere os campos em azul em "Tabela_Preço" e "Materiais"
B8: esta Planilha
H9: Altere somente os campos em azul, de acordo com a sua
H10: realidade. Por exemplo, pode ser que o seu estúdio cobre 50%
H11: de comissão. Faça essa alteração.
B12: Um guia Rápido para Você Calcular
B13: Valores Base para suas Tatuagens | H13: 03. Altere os campos em azul na aba "Calculadora"
H15: Altere os campos em azul de acordo com o seu valor/hora, a
H16: quantidade de horas para execução da tatuagem, a quantidade
H17: de horas para execução do desenho e as taxas da sua máquina.
H19: 04. E pronto!
H21: No campo "COBRAR" você vai encontrar o valor
H22: que deveria cobrar pela tatuagem.
B23: Criada por LORENA MELO

Sheet Tabela_Preço
C1: VALORES BASE
C3: *Esses valores irão servir como BASE para seu cálculo. O valor mais exato poderá ser feito na aba 'calculadora'.
C4: *Alterar somente os valores em AZUL.
C6: VALOR IDEAL A SOMAR NO SEU TRABALHO BASE
C7: 30% do estúdio + 10% material e reserva.
C8: % estúdio (%E) | D8: 0.3 | E8: * Altere de acordo com o seu estúdio.
C9: %material & reserva (MR) | D9: =10% -> 0.1 | E9: * Altere de acordo com a sua realidade.
C10: Total % (T%) | D10: =D8+D9 -> 0.4
C12: Tabela de Preços Médios Para Propostas com base em TAMANHO em cm
C13: Tamanho (cm) | D13: Preço Mínimo | E13: Preço Máximo | F13: Preço Mínimo COBRAR | G13: Preço Máximo COBRAR
C14: 8 - 10 cm | D14: 650 | E14: 950 | F14: =D14+(D14*$D$10) -> 910 | G14: =E14+(E14*$D$10) -> 1330
C15: 10-15 cm | D15: 950 | E15: 1200 | F15: =D15+(D15*$D$10) -> 1330 | G15: =E15+(E15*$D$10) -> 1680
C16: 15-20 cm | D16: 1200 | E16: 1450 | F16: =D16+(D16*$D$10) -> 1680 | G16: =E16+(E16*$D$10) -> 2030
C17: 20 - 25 cm | D17: 1450 | E17: 1800 | F17: =D17+(D17*$D$10) -> 2030 | G17: =E17+(E17*$D$10) -> 2520
C18: 25 - 30 cm | D18: 1800 | E18: 2200 | F18: =D18+(D18*$D$10) -> 2520 | G18: =E18+(E18*$D$10) -> 3080
C19: *valores finais somados a 40%: 30% porcentagem do estúdio + 10% de reserva para material.
C24: Valores de Sessões com base em TEMPO/hora
C25: Sessão Hora (SH) | D25: Valor Líquido (VL) | E25: Valor Cobrado (VC)
C26: 8 | D26: =8*D30 -> 1600 | E26: =D26+(D26*$D$10) -> 2240
C27: 6 | D27: =6*D30 -> 1200 | E27: =D27+(D27*$D$10) -> 1680
C28: 5 | D28: =5*D30 -> 1000 | E28: =D28+(D28*$D$10) -> 1400
C29: 4 | D29: =4*D30 -> 800 | E29: =D29+(D29*$D$10) -> 1120
C30: hora de trabalho (HT) = | D30: 200 | F30: * Altere aqui o valor da sua hora de trabalho.
C31: VL = SH * HT | D31: VC = VL * (T%) | F31: Isto fará com que o VL e VC se alterem também.

Sheet Material
B1: MATERIAL UTILIZADO
B2: *Alterar somente os valores em AZUL.
B3: *Altere os nomes das marcas que você usa.
E4: *Aqui você vai fazer a alteração para cada orçamento.
B7: Cartuchos | C7: Preço | D7: Linha | E7: Qtdade | F7: SubTotal
B8: Kwadron RL | C8: 20 | E8: 2 | F8: =E8*C8 -> 40 | H8: *Altere aqui quantos cartuchos você pretende usar no trabalho.
B9: Kwadron RS | C9: 20 | F9: =E9*C9 -> 0
B10: Kwadron MG | C10: 20 | F10: =E10*C10 -> 0
B11: Cheyenne RL | C11: 16 | D11: Craft | F11: =E11*C11 -> 0
B12: Cheyenne RS | C12: 16 | D12: Craft | F12: =E12*C12 -> 0
B13: Cheyenne MG | C13: 18 | D13: Craft | F13: =E13*C13 -> 0
F14: =E14*C14 -> 0
F15: =E15*C15 -> 0
B16: Total CARTUCHOS | F16: =SUM(F8:F15) -> 40
B17: Agulhas haste | C17: Preço | D17: Linha | E17: Qtdade | F17: SubTotal
B18: ElectricInk RL/RS | C18: 3.5 | D18: Perfect | E18: 2 | F18: =E18*C18 -> 7
B19: ElectricInk MG | D19: Perfect | F19: =E19*C19 -> 0
B20: ElectricInk RL/RS | D20: BlackCat | F20: =E20*C20 -> 0
B21: ElectricInk MG | C21: 4 | D21: BlackCat | F21: =E21*C21 -> 0
B22: ElectricInk RL/RS | D22: Premium | F22: =E22*C22 -> 0
B23: ElectricInk MG | C23: 6 | D23: Premium | F23: =E23*C23 -> 0
F24: =E24*C24 -> 0
B25: Total Agulhas de Haste | E25: =SUM(E18:E23) -> 2 | F25: =SUM(F18:F24) -> 7
B26: Biqueiras | C26: Preço | D26: Tipo | E26: Qtdade
B27: ElectricInk RL/RS | C27: 3.5 | E27: 2 | F27: =E27*C27 -> 7
B28: ElectricInk MG | C28: 4 | E28: 0 | F28: =E28*C28 -> 0
B29: Total Biqueiras | E29: =SUM(E27:E28) -> 2 | F29: =SUM(F27:F28) -> 7
B30: Total AGULHAS E BIQUEIRAS | F30: =F25+F29 -> 14
B33: CÁLCULO QTDE DE LUVAS, TINTA E TRANSFER | G33: Tatuagens por ano ( Tattoos / ano) :
B34: Pares por caixa | C34: 50 | G34: Altere aqui aproximadamente quantas tatuagens você faz por ano.
B35: Tattoos / ano | C35: =192 -> 192 | G35: Isso pode ser calculado pensando em quantas em média você faz por mês.
B36: Pares de Luvas/tattoo | C36: 20
B37: Valor/par MEDIX | C37: =C53/50 -> 0.9
B38: Valor/par SUPERMAX | C38: =C54/50 -> 2.2
B40: Tinta (240ml) | C40: Preço/frasco | D40: Qtde/ano? | E40: Valor cobrar/ttt | G40: Valor da tinta e transfer :
B41: JetBlack | C41: 290 | D41: 4 | E41: =(C41*D41)/C35 -> 6.0416667 | G41: Altere aqui por quanto você tem comprado sua tinta e transfer.
B42: Dynamic | C42: 550 | D42: 4 | E42: =(C42*D42)/C35 -> 11.458333
B43: Tinta Vermelha | C43: 150 | D43: 1 | E43: =(C43*D43)/C35 -> 0.78125
B44: Tinta Azul
B45: Etc
...

Sheet Apps Pagos & Tráfego
A1: MENSALIDADE DE APPS UTILIZADOS & TRÁFEGO PAGO
A3: Tattoos/mês | B3: 16
A5: Mensalidades (Fixas) | F5: Tráfego Pago (variável)
A6: App | B6: Valor | F6: Ad | G6: Valor Colocado/mês
A7: Apple iCloud | B7: 21.9 | F7: Google Ads | G7: 0
A8: Google Cloud | B8: 0 | F8: Instagram Ads | G8: 250
A9: Adobe Pack Simples | B9: 56 | F9: Total | G9: =SUM(G7:G8) -> 250
A10: Canva | B10: 45 | F10: Cobrar na tattoo | G10: =G9/B3 -> 15.625
A11: Acuity | B11: 100
A12: Wix | B12: 35
A14: Total | B14: =SUM(B7:B12) -> 257.9
A15: Cobrar na tattoo | B15: =B14/B3 -> 16.11875

Sheet Calculadora
B1: CALCULADORA
B2: * Aqui você encontrará o valor CALCULADO sugerido/mais próximo do que você deveria cobrar.
C3: * Altere aqui a quantidade de horas de trabalho e o valor da sua hora, tanto para tatuagem quanto para criação da arte.
C5: *Alterar somente os valores escritos em AZUL.
B7: Item/Serviço | C7: Quantidade | D7: Valor/hora ou Quantidade | E7: Sub Total | G7: Juros Máquina Cartão | I7: Valor parcelado
B8: Horas de Sessão Prevista | C8: 5 | D8: 200 | E8: =C8*D8 -> 1000 | G8: 2x | H8: 0.098 | I8: =D55 -> 1956.6618
B9: Materiais | C9: 1 | E9: =Material!C56 -> 79.604167 | G9: 3x | H9: 0.111 | I9: =E55 -> 1999.8479
B10: Apps/Assinaturas | C10: 1 | E10: ='Apps Pagos & Tráfego'!B15 -> 16.11875 | G10: 4x | H10: 0.125 | I10: =F55 -> 2048.5399
B11: Tráfego Pago | C11: 1 | E11: ='Apps Pagos & Tráfego'!G10 -> 15.625 | G11: 5x | H11: 0.138 | I11: =G55 -> 2095.926
B12: Criação/Concepção | C12: 0 | D12: 120 | E12: =D12*C12 -> 0 | G12: 6x | H12: 0.151 | I12: =H55 -> 2145.5563
B13: Depreciação de Eletrônicos | C13: 1 | D13: =Depreciação!B24 -> 6.5625 | E13: =D13*C13 -> 6.5625 | G13: 7x | H13: 0.164 | I13: =I55 -> 2197.5941
B14: Custos Administrativos/Lanche | C14: 1 | D14: 60 | E14: =D14*C14 -> 60 | G14: 8x | H14: 0.177 | I14: =J55 -> 2252.2188
D15: Total | E15: =SUM(E8:E14) -> 1177.9104 | G15: 9x | H15: 0.19 | I15: =K55 -> 2309.6283
G16: 9x | H16: 0.201
D17: Sub total | E17: =E15+E16 -> 1177.9104 | G17: 10x | H17: 0.21 | I17: =L55 -> 2403.8988
D18: COBRAR (SEM JUROS) | E18: =C37 -> 1682.7292 | G18: * altere aqui a porcentagem de juros cobrada pela sua máquina.
D19: COBRAR (COM JUROS) | E19: =L55 -> 2403.8988
D20: A receber | E20: =E18-(E18*(0.3)) -> 1177.9104 | G20: 1. O valor com juros está padrão como 10x.
G21: 2. COBRAR(SEM JUROS): este valor já inclui a comissão do estúdio.
B22: *materiais = cartuchos + agulhas + tinta + luvas + transfer + sabão.
B28: A seguir, o cálculo de como é chegar no valor a ser cobrado SEM e COM JUROS, caso você queira embutir no valor.
B29: Use o SEM JUROS se você for dar essa opção separada para o cliente - ele decide se quer parcelar e arca com a diferença
B30: - a mesma coisa que acontece aqui no COM JUROS, porém aqui estava embutido, para você ter uma noção de quanto ficaria parcelado.
B32: SEM JUROS
C33: Parcelas: | D33: 2x | E33: 3x | F33: 4x | G33: 5x | H33: 6x | I33: 7x | J33: 8x | K33: 9x | L33: 10x
B34: Cálculo: | C34: x = 1082 + % máquina (x) + % estúdio (x) x - 0,3x - Mx = 1082 (M = % máquina) | D34: x - 0,3x - 0,098x | E34: x - 0,3x - 0,111x | F34: x - 0,3x - 0,125x | G34: x - 0,3x - 0,138x | H34: x - 0,3x - 0,151x | I34: x - 0,3x - 0,164x | J34: x - 0,3x - 0,177x | K34: x - 0,3x - 0,19x | L34: x - 0,3x - 0,201x
C36: Fator de multiplicação | D36: =1-(Tabela_Preço!D8) -> 0.7 | E36: =1-(Tabela_Preço!D8) -> 0.7 | F36: =1-(Tabela_Preço!D8) -> 0.7 | G36: =1-(Tabela_Preço!D8) -> 0.7 | H36: =1-(Tabela_Preço!D8) -> 0.7 | I36: =1-(Tabela_Preço!D8) -> 0.7 | J36: =1-(Tabela_Preço!D8) -> 0.7 | K36: =1-(Tabela_Preço!D8) -> 0.7 | L36: =1-(Tabela_Preço!D8) -> 0.7
B37: Valor a cobrar: | C37: =J40 -> 1682.7292 | D37: =C39/D36 -> 1682.7292 | E37: =C39/E36 -> 1682.7292 | F37: =C39/F36 -> 1682.7292 | G37: =C39/G36 -> 1682.7292 | H37: =C39/H36 -> 1682.7292 | I37: =C39/I36 -> 1682.7292 | J37: =C39/J36 -> 1682.7292 | K37: =C39/K36 -> 1682.7292 | L37: =C39/L36 -> 1682.7292
B38: % Máquina: | C38: variado | D38: 0.098 | E38: 0.111 | F38: 0.125 | G38: 0.138 | H38: 0.151 | I38: 0.164 | J38: 0.177 | K38: 0.19 | L38: 0.201
B39: Valor a receber: | C39: =E17 -> 1177.9104
B40: % Estúdio: | C40: 0.3 | I40: Valor a cobrar: | J40: =C39/H36 -> 1682.7292
B42: Para tudo: | C42: Valor a cobrar = valor a receber + 30% do valor a cobrar + %parcelamento sobre o valor a cobrar
C43: OU Valor a cobrar (VC) * Fator de Multiplicação (FM) = Valor a receber (VR)
D44: Exemplo: | E44: VC *FM = VR
E45: VC*0,602 = 1797,34
B49: COM JUROS
C50: Parcelas: | D50: 2x | E50: 3x | F50: 4x | G50: 5x | H50: 6x | I50: 7x | J50: 8x | K50: 9x | L50: 10x
B51: Cálculo: | C51: x = 1082 + % máquina (x) + % estúdio (x) x - 0,3x - Mx = 1082 (M = % máquina) | D51: x - 0,3x - 0,098x | E51: x - 0,3x - 0,111x | F51: x - 0,3x - 0,125x | G51: x - 0,3x - 0,138x | H51: x - 0,3x - 0,151x | I51: x - 0,3x - 0,164x | J51: x - 0,3x - 0,177x | K51: x - 0,3x - 0,19x | L51: x - 0,3x - 0,201x
C53: Fator de multiplicação | D53: =1-Tabela_Preço!D8-D56 -> 0.602 | E53: =1-Tabela_Preço!D8-E56 -> 0.589 | F53: =1-Tabela_Preço!D8-F56 -> 0.575 | G53: =1-Tabela_Preço!D8-G56 -> 0.562 | H53: =1-Tabela_Preço!D8-H56 -> 0.549 | I53: =1-Tabela_Preço!D8-I56 -> 0.536 | J53: =1-Tabela_Preço!D8-J56 -> 0.523 | K53: =1-Tabela_Preço!D8-K56 -> 0.51 | L53: =1-Tabela_Preço!D8-L56 -> 0.49
C54: Fórmula básica | D54: X = 1082 / (1-0,3-0,098) = 1797 << cálculo igual para todos, mudando apenas o % do parcelamento
...

Sheet Depreciação
A1: DEPRECIAÇÃO DE ELETRÔNICOS
A2: DA = (VI – VR)/VU
A4: Depreciação iPad
A5: DA = Depreciação anual
A6: VI = Valor inicial ou de aquisição | B6: =3500 -> 3500
A7: VR = Valor residual ou de sucata | B7: 500
A8: VU = Vida útil | B8: 5 | C8: anos
A10: DA = | B10: =(B6-B7)/B8 -> 600
B11: Desta forma, anualmente o equipamento trará um custo adicional às suas despesas.
A13: Depreciação Máquina Tattoo
A14: DA = Depreciação anual
A15: VI = Valor inicial ou de aquisição | B15: =4500 -> 4500
A16: VR = Valor residual ou de sucata | B16: 1200
A17: VU = Vida útil | B17: 5 | C17: anos
A19: DA = | B19: =(B15-B16)/B17 -> 660
B20: Desta forma, anualmente o equipamento trará um custo adicional às suas despesas.
A22: Depreciação total dos eletrônicos/ano | B22: =B10+B19 -> 1260
A23: tattoos por ano | B23: 192
A24: Depreciação a ser dividida/trabalho | B24: =B22/B23 -> 6.5625
